---
version: 1.4.1
title: When javascript throws,\n  call_function should return an exception value
---
[1mOk[0m(ExceptionResult[0m(EvaluateResultException[0m(
  Exception[0m,
  ExceptionDetails[0m(
    [38;5;3m35[0m,
    ErrorRemote[0m(ErrorRemoteValue[0m(
      [38;5;2m"error"[0m,
      [1mNone[0m,
      [1mNone[0m,
    )),
    [38;5;3m0[0m,
    StackTrace[0m([
      StackFrame[0m(
        [38;5;3m35[0m,
        [38;5;2m"test_exception"[0m,
        [38;5;3m0[0m,
        [38;5;2m"about:blank"[0m,
      ),
      StackFrame[0m(
        [38;5;3m67[0m,
        [38;5;2m""[0m,
        [38;5;3m0[0m,
        [38;5;2m"about:blank"[0m,
      ),
    ]),
    [38;5;2m"Error: Test exception"[0m,
  ),
)))
